from django.core.exceptions import ValidationError


def user_username_validator():
    pass